# 第八章：错误处理 Error Handling


## 8.8 错误链 Chaining Errors
	
本小节主要讲了如何```优雅的```处理链式调用多个可能抛出错误的方法。

##### 其实swift 的内建(build-in)错误处理处理机制就已经很好的将链式调用可能抛错的方法，我们直接用一个大的do/catch块把这一段```包裹```住就行。


##### 但是作为一个优秀的开发者，我们可以用更优雅的解决方案去处理这种场景。
还记得之前学的```Result```类么? 我们可以通过Result类去包装返回值，让你的代码变得更加优雅。

具体Demo如下

    ///未通过Result包装error的检查文件和返回pid的方法
    func checkFilesAndFetchProcessID(filenames: [String]) -> Int {
         do {
        try filenames.all(checkFile)
            let contents = try contentsOfFile("Pidfile") 
            return try optional(Int(contents),
            orError: ReadIntError.CouldNotRead) }
         catch {
            return 42 // 默认值 
        }
    }

    ///通过Result包装error的检查文件和返回pid的方法，毫无try catch 痕迹可言。 
    func checkFilesAndFetchProcessID(filenames: [String]) -> Result<Int> { 
        return filenames
        . all (checkFile)
        .flatMap { _ in contentsOfFile("Pidfile") } 
        .flatMap { contents in
        Int ( contents).map(Result.Success) ?? .Failure(ReadIntError.CouldNotRead)
        } 
    }

##### 注: 这里实际上是通过一系列的flatMap方法去过滤掉error， 在实际开发中，我们可以通过同样可以通过flatmap做很多关于去除nil的骚操作， 这个知识点之前有听过瞄神提过。我们项目中就有许多场景使用到，小伙伴们不妨在自己的项目中也尝试一下~


